<?xml version="1.0"?>
<robot name="burt">

	<material name="gray">
		<color rgba="0.75 0.75 0.75 2"/>
	</material>

	<material name="dark_gray">
		<color rgba="0.25 0.25 0.25 2"/>
	</material>

	<material name="red">
		<color rgba="1 0 0 2"/>
	</material>

	<link name="base_link">
		<visual>
			<geometry>
				<box size="0.31 0.22 0.04"/>
			</geometry>
			<material name="red"/>
		</visual>
		<collision>
			<geometry>
				<box size="0.31 0.22 0.04"/>
			</geometry>
		</collision>
		<inertial>
			<mass value="15"/>
			<inertia ixx="0.125" ixy="0" ixz="0" iyy="0.166" iyz="0" izz="0.266"/>
		</inertial>
	</link>

	<link name="right_front_wheel">
		<visual>
			<geometry>
				<cylinder length="0.045" radius="0.085"/>
			</geometry>
			<origin rpy="1.57075 0 0" xyz="0 -0.03 0"/>
			<material name="dark_gray"/>
		</visual>
		<collision>
			<geometry>
				<cylinder length="0.045" radius="0.085"/>
			</geometry>
			<origin rpy="1.57075 0 0" xyz="0 -0.03 0"/>
		</collision>
		<inertial>
			<mass value="3"/>
			<inertia ixx="0.006" ixy="0" ixz="0" iyy="0.006" iyz="0" izz="0.011"/>
		</inertial>
	</link>
	<joint name="front_right_wheel_joint" type="continuous">
		<parent link="base_link"/>
		<child link="right_front_wheel"/>
		<origin xyz="0.09 -0.12 -0.025"/>
		<axis rpy="0 0 0" xyz="0 1 0"/>
	</joint>

	<link name="right_back_wheel">
		<visual>
			<geometry>
				<cylinder length="0.045" radius="0.085"/>
			</geometry>
			<origin rpy="1.57075 0 0" xyz="0 -0.03 0"/>
			<material name="dark_gray"/>
		</visual>
		<collision>
			<geometry>
				<cylinder length="0.045" radius="0.085"/>
			</geometry>
			<origin rpy="1.57075 0 0" xyz="0 -0.03 0"/>
		</collision>
		<inertial>
			<mass value="3"/>
			<inertia ixx="0.006" ixy="0" ixz="0" iyy="0.006" iyz="0" izz="0.011"/>
		</inertial>
	</link>
	<joint name="back_right_wheel_joint" type="continuous">
		<parent link="base_link"/>
		<child link="right_back_wheel"/>
		<origin xyz="-0.09 -0.12 -0.025"/>
		<axis rpy="0 0 0" xyz="0 1 0"/>
	</joint>

	<link name="left_front_wheel">
		<visual>
			<geometry>
				<cylinder length="0.045" radius="0.085"/>
			</geometry>
			<origin rpy="1.57075 0 0" xyz="0 0.03 0"/>
			<material name="dark_gray"/>
		</visual>
		<collision>
			<geometry>
				<cylinder length="0.045" radius="0.085"/>
			</geometry>
			<origin rpy="1.57075 0 0" xyz="0 0.03 0"/>
		</collision>
		<inertial>
			<mass value="3"/>
			<inertia ixx="0.006" ixy="0" ixz="0" iyy="0.006" iyz="0" izz="0.011"/>
		</inertial>
	</link>
	<joint name="front_left_wheel_joint" type="continuous">
		<parent link="base_link"/>
		<child link="left_front_wheel"/>
		<origin xyz="0.09 0.12 -0.025"/>
		<axis rpy="0 0 0" xyz="0 1 0"/>
	</joint>

	<link name="left_back_wheel">
		<visual>
			<geometry>
				<cylinder length="0.045" radius="0.085"/>
			</geometry>
			<origin rpy="1.57075 0 0" xyz="0 0.03 0"/>
			<material name="dark_gray"/>
		</visual>
		<collision>
			<geometry>
				<cylinder length="0.045" radius="0.085"/>
			</geometry>
			<origin rpy="1.57075 0 0" xyz="0 0.03 0"/>
		</collision>
		<inertial>
			<mass value="3"/>
			<inertia ixx="0.006" ixy="0" ixz="0" iyy="0.006" iyz="0" izz="0.011"/>
		</inertial>
	</link>
	<joint name="back_left_wheel_joint" type="continuous">
		<parent link="base_link"/>
		<child link="left_back_wheel"/>
		<origin xyz="-0.09 0.12 -0.025"/>
		<axis rpy="0 0 0" xyz="0 1 0"/>
	</joint>

<!-- This block provides the simulator (Gazebo) with information on a few additional
physical properties. See http://gazebosim.org/tutorials/?tut=ros_urdf for more-->
<gazebo reference="right_front_wheel">
  <mu1 value="200.0"/>
  <mu2 value="100.0"/>
  <kp value="10000000.0" />
  <kd value="1.0" />
  <material>Gazebo/Grey</material>
</gazebo>

<gazebo reference="right_back_wheel">
  <mu1 value="200.0"/>
  <mu2 value="100.0"/>
  <kp value="10000000.0" />
  <kd value="1.0" />
  <material>Gazebo/Grey</material>
</gazebo>

<gazebo reference="left_front_wheel">
  <mu1 value="200.0"/>
  <mu2 value="100.0"/>
  <kp value="10000000.0" />
  <kd value="1.0" />
  <material>Gazebo/Grey</material>
</gazebo>

<gazebo reference="left_back_wheel">
  <mu1 value="200.0"/>
  <mu2 value="100.0"/>
  <kp value="10000000.0" />
  <kd value="1.0" />
  <material>Gazebo/Grey</material>
</gazebo>


<!-- This block connects the wheel joint to an actuator (motor), which informs both
simulation and visualization of the robot -->
<transmission name="base_to_right_front_wheel_trans">
  <type>transmission_interface/SimpleTransmission</type>
  <actuator name="base_to_right_front_wheel_motor">
    <mechanicalReduction>1</mechanicalReduction>
  </actuator>
  <joint name="front_right_wheel_joint">
    <hardwareInterface>VelocityJointInterface</hardwareInterface>
  </joint>
</transmission>

<transmission name="base_to_right_back_wheel_trans">
  <type>transmission_interface/SimpleTransmission</type>
  <actuator name="base_to_right_back_wheel_motor">
    <mechanicalReduction>1</mechanicalReduction>
  </actuator>
  <joint name="back_right_wheel_joint">
    <hardwareInterface>VelocityJointInterface</hardwareInterface>
  </joint>
</transmission>

<transmission name="base_to_left_front_wheel_trans">
  <type>transmission_interface/SimpleTransmission</type>
  <actuator name="base_to_left_front_wheel_motor">
    <mechanicalReduction>1</mechanicalReduction>
  </actuator>
  <joint name="front_left_wheel_joint">
    <hardwareInterface>VelocityJointInterface</hardwareInterface>
  </joint>
</transmission>

<transmission name="base_to_left_back_wheel_trans">
  <type>transmission_interface/SimpleTransmission</type>
  <actuator name="base_to_left_back_wheel_motor">
    <mechanicalReduction>1</mechanicalReduction>
  </actuator>
  <joint name="back_left_wheel_joint">
    <hardwareInterface>VelocityJointInterface</hardwareInterface>
  </joint>
</transmission>

<gazebo>
	<plugin name="gazebo_ros_control" filename="libgazebo_ros_control.so">
	<robotNamespace>/</robotNamespace>
	</plugin>
</gazebo>

</robot>